<?xml version="1.0"?>
<robot xmlns:xacro="http://www.ros.org/wiki/xacro">
    <!-- 定义 imu_link 宏 -->
    <xacro:macro name="wheel_xacro" params="wheel_name xyz">
        <link name="${wheel_name}">
            <visual>
                <origin xyz="0.0 0.0 0.0" rpy="1.5708 0.0 0.0"/>
                <geometry>
                    <cylinder radius="0.032" length="0.04"/>
                </geometry>
                <material name="yellow"> 
                    <color rgba="1.0 1.0 0.0 0.8"/>
                </material>
            </visual>
        </link>
        <joint name="${wheel_name}_joint" type="continuous">
            <parent link="base_link"/>
            <child link="${wheel_name}"/>
            <origin xyz="${xyz}" rpy="0.0 0.0 0.0"/>
            <axis xyz="0.0 1.0 0.0"/>
        </joint>
    </xacro:macro>

</robot>